#VRML_SIM R2022a utf8
WorldInfo {
  basicTimeStep 16
}
Viewpoint {
  orientation -0.14813338528481113 0.021348900855483608 0.988736933969964 2.7463924513513964
  position 0.547026774784074 -0.10189864380822587 0.18904083119956616
}
TexturedBackground {
}
TexturedBackgroundLight {
}
RectangleArena {
  translation 4.69286e-08 0 -0.07
  rotation 0 1 0 4.692820414042842e-06
  floorTileSize 2 2
  wallThickness 0.05
}
Robot {
  translation 0 0 -0.04
  rotation 0 1 0 0
  children [
    DistanceSensor {
      translation -0.077 0.02 0
      rotation 0 0 1 1.5708
      name "leftSensor2"
      lookupTable [
        0 0 0
        0.2 1000 0
      ]
      type "infra-red"
    }
    DistanceSensor {
      translation -0.045 0.066 0
      rotation 0 0 1 0.584055
      name "leftSensor1"
      lookupTable [
        0 0 0
        0.2 1000 0
      ]
      type "infra-red"
      aperture 1.5709
    }
    DistanceSensor {
      translation 0.077 0.02 0
      rotation 0 0 1 -1.5707953071795862
      name "rightSensor2"
      lookupTable [
        0 0 0
        0.2 1000 0
      ]
    }
    DistanceSensor {
      translation 0.045 0.066 0.00258815
      rotation 0 0 -0.9999999999999999 0.584055
      name "rightSensor1"
      lookupTable [
        0 0 0
        0.2 1000 0
      ]
    }
    DistanceSensor {
      translation 0 0.08 0
      name "frontSensor"
      lookupTable [
        0 0 0
        0.2 1000 0
      ]
    }
    Solid {
      children [
        Shape {
          appearance Appearance {
            material Material {
              diffuseColor 0.0721141 0.15172 0.366674
            }
            texture ImageTexture {
            }
          }
          geometry Cylinder {
            height 0.009
            radius 0.080001
          }
        }
      ]
      name "fixBorder"
    }
    Solid {
      translation 0 0.035 -0.012
      children [
        Shape {
          geometry Box {
            size 0.025 0.035 0.025
          }
        }
      ]
      name "ballSupport"
    }
    HingeJoint {
      jointParameters HingeJointParameters {
        axis 1 1 0
      }
      device [
        RotationalMotor {
        }
      ]
      endPoint Solid {
        translation -6.6174449004242214e-24 0.04000000000000003 -0.02500000000000001
        rotation 0.7071067811865475 0.7071067811865475 0 0
        children [
          Shape {
            appearance PBRAppearance {
            }
            geometry Sphere {
              radius 0.008
            }
          }
        ]
        name "solid(1)"
        boundingObject Sphere {
          radius 0.008
          subdivision 2
        }
        physics Physics {
        }
      }
    }
    Solid {
      translation 0.04 -0.03 -0.01
      rotation 0 1 0 1.5708
      children [
        Shape {
          appearance PBRAppearance {
          }
          geometry Cylinder {
            height 0.04
            radius 0.01
          }
        }
      ]
      name "shapeMotor2"
      boundingObject Cylinder {
        height 0.04
        radius 0.01
      }
      physics Physics {
        mass 3
      }
    }
    Solid {
      translation -0.04 -0.03 -0.00999976
      rotation 0 1 0 1.5708
      children [
        Shape {
          appearance PBRAppearance {
          }
          geometry Cylinder {
            height 0.04
            radius 0.01
          }
        }
      ]
      name "shapeMotor1"
      boundingObject Cylinder {
        height 0.04
        radius 0.01
      }
      physics Physics {
        mass 3
      }
    }
    HingeJoint {
      jointParameters HingeJointParameters {
        axis -1 0 0
        anchor 0.07 -0.03 -0.01
      }
      device [
        RotationalMotor {
          name "wheelRight"
        }
      ]
      endPoint Solid {
        translation 0.07 -0.03 -0.009999880000000003
        rotation 7.850447534108419e-17 1 -7.850447534108419e-17 1.5708000869179382
        children [
          Shape {
            geometry Cylinder {
              height 0.01
              radius 0.02
            }
          }
        ]
        boundingObject Cylinder {
          height 0.01
          radius 0.02
        }
        physics Physics {
        }
      }
    }
    HingeJoint {
      jointParameters HingeJointParameters {
        axis -1 0 0
        anchor -0.07 -0.03 -0.01
      }
      device [
        RotationalMotor {
          name "wheelLeft"
        }
      ]
      endPoint Solid {
        translation -0.07 -0.03 -0.01
        rotation 7.850448216423499e-17 1 -7.850448216423499e-17 1.5707999130889807
        children [
          Shape {
            geometry Cylinder {
              height 0.01
              radius 0.02
            }
          }
        ]
        boundingObject Cylinder {
          height 0.01
          radius 0.02
        }
        physics Physics {
        }
      }
    }
    Shape {
      appearance Appearance {
        material Material {
          diffuseColor 0.325882 0.43929 0.0835294
        }
        texture ImageTexture {
          url [
            "https://raw.githubusercontent.com/AntoineToullalan/Projet_ANDROIDE_Robots_en_essaim/main/simulation/texture_mona.png"
          ]
        }
      }
      geometry Cylinder {
        height 0.01
        radius 0.08
      }
    }
  ]
  name "mona"
  boundingObject Cylinder {
    height 0.01
    radius 0.08
  }
  physics Physics {
    mass 10
  }
  controller "first_mona_controller"
}
CardboardBox {
  translation -0.4 0 0.02
  size 0.2 0.2 0.2
}
Elisa3 {
  translation 0 0.22 -0.07
  controller "braitenberg"
}
